Workbook

Sheet Planilha1
A1: CÓDIGO TRUCKPARTS | B1: DESCRIÇÃO | C1: QTD | D1: MATÉRIA PRIMA | E1: PESO LÍQUIDO UNITÁRIO | F1: PESO BRUTO | G1: % DE PERCA
A2: RN 01001 | B2: BALANÇA ASA DELTA CARRETA PINO Ø 50MM
A3: TP 01001A | B3: LATERAL 5/16" BALANÇA CARRETA ASA DELTA LS PINO Ø 50MM | C3: 2 | D3: CHAPA DE AÇO 5/16" | E3: 3.71 | F3: 4.71 | G3: =(F3/E3)-1 -> 0.26954178
A4: TP 01001B | B4: PEITO DE POMBO 170 X 94 X 3/8" | C4: 2 | D4: CHAPA DE AÇO 3/8" | E4: 1.22 | F4: 1.32 | G4: =(F4/E4)-1 -> 0.081967213
A5: TP 01001C | B5: FECHAMENTO SUPERIOR 504 X 102 X 3MM | C5: 1 | D5: CHAPA DE AÇO 3MM | E5: 1.23 | F5: 1.35 | G5: =(F5/E5)-1 -> 0.097560976
A6: TP 01001D | B6: FECHAMENTO INFERIOR 130 X 94 X 3MM | C6: 1 | D6: CHAPA DE AÇO 3MM | E6: 0.24 | F6: 0.27 | G6: =(F6/E6)-1 -> 0.125
A7: BU 0120/50 | B7: BUCHA DA BALANÇA 120MM PARA PINO 50MM | C7: 1 | D7: BUCHA EXTERNA + BUCHA INTERNA | E7: =E8+E9+E9 -> 2.25 | F7: =F8+F9+F9 -> 2.295 | G7: =(F7/E7)-1 -> 0.02
A8: BU 0120E | B8: BUCHA EXTERNA 120MM | C8: 1 | D8: CHAPA DE AÇO 5/16" | E8: 1.65 | F8: 1.683 | G8: =(F8/E8)-1 -> 0.02
A9: - | B9: BUCHA INTERNA 50,4MM ACABADA | C9: 2 | D9: TUBO DE AÇO REDONDO Ø60,3 X 4,75 | E9: 0.3 | F9: 0.306 | G9: =(F9/E9)-1 -> 0.02
A10: - | B10: BUCHA INTERNA 50,4MM SEMI-ACABADA | C10: 2 | D10: TUBO DE AÇO REDONDO Ø60,3 X 4,75 | E10: 0.3 | F10: 0.306 | G10: =(F10/E10)-1 -> 0.02
A12: Código: | B12: =A3 -> TP 01001A
A13: Descrição: | B13: =B3 -> LATERAL 5/16" BALANÇA CARRETA ASA DELTA LS PINO Ø 50MM
A14: Lote Economico: | B14: 200
A15: Quantidade: | B15: =C3 -> 2
A16: Processo | B16: Tempo de Setup | C16: Custo de Setup | D16: Tempo de Processo | E16: Custo de Processo
A17: Cortar no Laser | B17: 180 | C17: =(B17*'Hora maquina'!C2)/B14 -> 0.0296375 | D17: 85 | E17: =D17*'Hora maquina'!C2 -> 2.7990972
A18: CUSTO TOTAL | E18: =(C17+E17)*B15 -> 5.6574694
A20: Código: | B20: =A4 -> TP 01001B
A21: Descrição: | B21: =B4 -> PEITO DE POMBO 170 X 94 X 3/8"
A22: Lote Economico: | B22: 200
A23: Quantidade: | B23: =C4 -> 2
A24: Processo | B24: Tempo de Setup | C24: Custo de Setup | D24: Tempo de Processo | E24: Custo de Processo
A25: Cortar na Guilhotina | B25: 300 | C25: =(B25*'Hora maquina'!C4)/B22 -> 0.0230125 | D25: 15 | E25: =D25*'Hora maquina'!C4 -> 0.230125
A26: Repicar na Guilotina | B26: 300 | C26: =(B26*'Hora maquina'!C4)/B22 -> 0.0230125 | D26: 15 | E26: =D26*'Hora maquina'!C4 -> 0.230125
A27: Dobrar na Prensa | B27: 600 | C27: =(B27*'Hora maquina'!C6)/B22 -> 0.034716667 | D27: 20 | E27: =D27*'Hora maquina'!C6 -> 0.23144444
A28: CUSTO TOTAL | E28: =(C25+E25+C27+E27+C26+E26)*B23 -> 1.5448722
A30: Código: | B30: =A5 -> TP 01001C
A31: Descrição: | B31: =B5 -> FECHAMENTO SUPERIOR 504 X 102 X 3MM
A32: Lote Economico: | B32: 100
A33: Quantidade: | B33: =C5 -> 1
A34: Processo | B34: Tempo de Setup | C34: Custo de Setup | D34: Tempo de Processo | E34: Custo de Processo
A35: Cortar na Guilhotina | B35: 300 | C35: =(B35*'Hora maquina'!C4)/B32 -> 0.046025 | D35: 15 | E35: =D35*'Hora maquina'!C4 -> 0.230125
A36: Repicar na Guilhotina | B36: 300 | C36: =(B36*'Hora maquina'!C4)/B32 -> 0.046025 | D36: 15 | E36: =D36*'Hora maquina'!C4 -> 0.230125
A37: Dobrar na Dobradeira | B37: 300 | C37: =(B37*'Hora maquina'!C3)/B32 -> 0.092208333 | D37: 20 | E37: =D37*'Hora maquina'!C4 -> 0.30683333
A38: CUSTO TOTAL | E38: =(C35+E35+C37+E37+C36+E36)*B33 -> 0.95134167
A40: Código: | B40: =A6 -> TP 01001D
A41: Descrição: | B41: =B6 -> FECHAMENTO INFERIOR 130 X 94 X 3MM
A42: Lote Economico: | B42: 100
A43: Quantidade: | B43: =C6 -> 1
A44: Processo | B44: Tempo de Setup | C44: Custo de Setup | D44: Tempo de Processo | E44: Custo de Processo
...

Sheet Hora maquina
A1: MÁQUINA | B1: CUSTO HORA MÁQUINA | C1: SEGUNDOS | G1: CHAPA 1200 X 3000 | H1: PESO UNITÁRIO
A2: Laser Calfran | B2: 118.55 | C2: 0.032930556 | G2: 3mm | H2: 84.78
A3: Dobradeira ERMAK 3300 | B3: 110.65 | C3: 0.030736111 | G3: 3/16" | H3: 134.24
A4: Guilhotina | B4: 55.23 | C4: 0.015341667 | G4: 1/4" | H4: 179.45
A5: Maquina de Solda | B5: 37.09 | C5: 0.010302778 | G5: 5/16" | H5: 226.08
A6: Prensa | B6: 41.66 | C6: 0.011572222 | G6: 3/8" | H6: 268.47
A7: Policorte | B7: 35.71 | C7: 0.0099194444 | G7: 1/2" | H7: 358.9
A8: Limpeza | B8: 25.79 | C8: 0.0071638889 | G8: 5/8" | H8: 448.77
A9: Pintura | B9: 63.513502 | C9: 0.017642639
A10: Furadeira | B10: 26.08 | C10: 0.0072444444
A11: Embalagem OPERADOR MÉDIO | B11: 25 | C11: 0.0069444444
A12: Serra Fita | B12: 39.93 | C12: 0.011091667
A14: VALOR DO AÇO (CHAPAS JANDAIA) | B14: 4.7
C17: 50mm | D17: 110mm
A18: Tubo Bucha Interna Pino 50mm | B18: 350.14 | C18: 3.2122936 | D18: -
A19: Tubo Bucha Interna Pino 60,4mm / 61,5mm | B19: 1130 | C19: 10
A20: Tubo Bucha Externa | B20: 813.35 | C20: - | D20: 15.346226
A22: Tabela de Cementação
A23: Até 50kg | B23: 300
A24: Acima de 50kg | B24: 5.8
