Workbook

Sheet Planilha1
A1: CÓDIGO TRUCKPARTS | B1: DESCRIÇÃO | C1: QTD | D1: Matéria Prima | E1: PESO LÍQUIDO UNITÁRIO | F1: PESO BRUTO | G1: % perca
A2: RN 01007 | B2: SUPORTE CENTRAL SR 2000 PINO 50MM
A3: TP 01007A | B3: Chapa 1/4" do Suporte SR 2000 Pino 50mm | C3: 1 | D3: Chapa de Aço 1/4" | E3: 10.2 | F3: 14.95 | G3: =(F3/E3)-1 -> 0.46568627
A4: TP 01007B | B4: Arruela 50 x 25 x 5/16" | C4: 2 | D4: Chapa de Aço 5/16" | E4: 0.16 | F4: 0.17 | G4: =(F4/E4)-1 -> 0.0625
A5: TP 01007C | B5: Reforço 1/4" Interno do Suporte Central SR 2000 | C5: 2 | D5: Chapa de Aço 1/4" | E5: 0.55 | F5: 0.83 | G5: =(F5/E5)-1 -> 0.50909091
A6: TP 01022A | B6: Chapa 1/2" Mancal do Suporte Central da Carreta Pino 50mm | C6: 2 | D6: Chapa de Aço 1/2" | E6: 0.76 | F6: 0.98 | G6: =(F6/E6)-1 -> 0.28947368
A7: TP 01007D | B7: Cantoneira 115 x 60 x 1/4" | C7: 1 | D7: Chapa de Aço 1/4" | E7: 0.35 | F7: 0.4 | G7: =(F7/E7)-1 -> 0.14285714
A8: TP 01007E | B8: Reforço 1/4" do Mancal Ferradura | C8: 2 | D8: Chapa de Aço 1/4" | E8: 0.32 | F8: 0.45 | G8: =(F8/E8)-1 -> 0.40625
A10: Código: | B10: =A3 -> TP 01007A
A11: Descrição: | B11: =B3 -> Chapa 1/4" do Suporte SR 2000 Pino 50mm
A12: Lote Economico: | B12: 100
A13: Quantidade: | B13: =C3 -> 1
A14: Processo | B14: Tempo de Setup | C14: Custo de Setup | D14: Tempo de Processo | E14: Custo de Processo
A15: Cortar no Laser | B15: 300 | C15: =(B15*'hora maquina'!C2)/B12 -> 0.098791667 | D15: 150 | E15: =D15*'hora maquina'!C2 -> 4.9395833
A16: Estampar na Prensa | B16: 1200 | C16: =B16*'hora maquina'!C6/B12 -> 0.13886667 | D16: 35 | E16: =D16*'hora maquina'!C6 -> 0.40502778
A17: Dobrar na Dobradeira | B17: 600 | C17: =(B17*'hora maquina'!C3)/B12 -> 0.18441667 | D17: 90 | E17: =D17*'hora maquina'!C3 -> 2.76625
A18: CUSTO TOTAL | E18: =C15+C16+C17+E15+E16+E17 -> 8.5329361
A20: Código: | B20: =A4 -> TP 01007B
A21: Descrição: | B21: =B4 -> Arruela 50 x 25 x 5/16"
A22: Lote Economico: | B22: 200
A23: Quantidade: | B23: 2
A24: Processo | B24: Tempo de Setup | C24: Custo de Setup | D24: Tempo de Processo | E24: Custo de Processo
A25: Cortar no Laser | B25: 300 | C25: =(B25*'hora maquina'!C2)/B22 -> 0.049395833 | D25: 10 | E25: =D25*'hora maquina'!C2 -> 0.32930556
A26: CUSTO TOTAL | E26: =(C25+E25)*B23 -> 0.75740278
A28: Código: | B28: =A5 -> TP 01007C
A29: Descrição: | B29: =B5 -> Reforço 1/4" Interno do Suporte Central SR 2000
A30: Lote Economico: | B30: 200
A31: Quantidade: | B31: 2
A32: Processo | B32: Tempo de Setup | C32: Custo de Setup | D32: Tempo de Processo | E32: Custo de Processo
A33: Cortar no Laser | B33: 300 | C33: =(B33*'hora maquina'!C2)/B30 -> 0.049395833 | D33: 20 | E33: =D33*'hora maquina'!C2 -> 0.65861111
A34: Dobrar na Dobradeira | B34: 300 | C34: =(B34*'hora maquina'!C3)/B30 -> 0.046104167 | D34: 70 | E34: =D34*'hora maquina'!C3 -> 2.1515278
A35: CUSTO TOTAL | E35: =(SUM(C33:C34)+SUM(E33:E34))*B31 -> 5.8112778
A37: Código: | B37: =A6 -> TP 01022A
A38: Descrição: | B38: =B6 -> Chapa 1/2" Mancal do Suporte Central da Carreta Pino 50mm
A39: Lote Economico: | B39: 100
A40: Quantidade: | B40: 2
A41: Processo | B41: Tempo de Setup | C41: Custo de Setup | D41: Tempo de Processo | E41: Custo de Processo
A42: Cortar no Laser | B42: 300 | C42: 0.098791667 | D42: 144 | E42: 4.742
A43: Dobrar na Prensa | B43: 1800 | C43: 0.2083 | D43: 35 | E43: 0.40502778
A44: CUSTO TOTAL | E44: 5.45
...

Sheet hora maquina
A1: MÁQUINA | B1: CUSTO HORA MÁQUINA | C1: SEGUNDOS | G1: CHAPA 1200 X 3000 | H1: PESO UNITÁRIO
A2: Laser Calfran | B2: 118.55 | C2: 0.032930556 | G2: 3mm | H2: 84.78
A3: Dobradeira ERMAK 3300 | B3: 110.65 | C3: 0.030736111 | G3: 3/16" | H3: 134.24
A4: Guilhotina | B4: 55.23 | C4: 0.015341667 | G4: 1/4" | H4: 179.45
A5: Maquina de Solda | B5: 37.09 | C5: 0.010302778 | G5: 5/16" | H5: 226.08
A6: Prensa | B6: 41.66 | C6: 0.011572222 | G6: 3/8" | H6: 268.47
A7: Policorte | B7: 35.71 | C7: 0.0099194444 | G7: 1/2" | H7: 358.9
A8: Limpeza | B8: 25.79 | C8: 0.0071638889 | G8: 5/8" | H8: 448.77
A9: Pintura | B9: 63.513502 | C9: 0.017642639
A10: Furadeira | B10: 26.08 | C10: 0.0072444444
A11: Embalagem OPERADOR MÉDIO | B11: 25 | C11: 0.0069444444
A12: Serra Fita | B12: 39.93 | C12: 0.011091667
A14: VALOR DO AÇO (CHAPAS JANDAIA) | B14: 4.7
C17: 50mm | D17: 110mm
A18: Tubo Bucha Interna Pino 50mm | B18: 350.14 | C18: 3.2122936 | D18: -
A19: Tubo Bucha Interna Pino 60,4mm / 61,5mm | B19: 1130 | C19: 10
A20: Tubo Bucha Externa | B20: 813.35 | C20: - | D20: 15.346226
A22: Tabela de Cementação
A23: Até 50kg | B23: 300
A24: Acima de 50kg | B24: 5.8
